Workbook

Sheet Recept-voorblad
A1: Receptuur | Q1: WP Lekker in de Kauw (Bird) 40(NIET AF)
A3: Naam bier | H3: Batch nr.: | K3: 26225
A5: Naam Brouwerij | E5: =IF(LEFT(Q1,2)="WP","Waarderpolder","Jopen Kerk")
A7: Bier stijl | E7: Aantal brouwsels | G7: 1 | H7: Datum orderpicken: | K7: -
A9: Brouwsel (hl) | E9: =IF(LEFT(Q1,2)="WP", "Kamers mashfilter","walsenmolen")
A10: Eindproduct specificaties
A11: Parameter | D11: Unit | E11: +/- | F11: Spec, | G11: Parameter | K11: Unit | L11: +/- | M11: Spec,
A12: Origineel extract | D12: °P | G12: Troebeling (Lab) | K12: EBC
A13: Rest extract | D13: °P | G13: CO2 fles | K13: g/l
A14: Alcohol | D14: v/v% | G14: CO2 Can | K14: g/l
A15: Bitterheid | D15: EBU | G15: CO2 fust | K15: g/l
A16: Kleur | D16: EBC | G16: Headspace O2 | K16: ppb | N16: Bier risico
A17: pH | G17: Dissolved O2 | K17: ppb
A18: ADF %
A19: Process paramaters
A20: Parameter | D20: Unit | E20: +/- | F20: Spec, | G20: Parameter | K20: Unit | L20: +/- | M20: Spec,
A21: =IF(LEFT(Q1,2)="WP", "Pitching Temp,","Wort koeling temp,") | D21: °C | G21: Vergistingstijd | K21: dagen | N21: Bier status
A22: Main Fermentation | D22: °C | G22: Lagertijd | K22: dagen
A23: T release, | D23: °C | G23: Lager temp, | K23: °C
A24: Temp, Dry, Warm, | D24: °C | G24: Pasteurisatie | K24: PU
A25: Extract dry, Warm 1 | D25: °P | G25: Troebeling na Sep | K25: EBC
A26: Extract dry, Warm 2 | D26: °P | G26: Bitterheid BH | K26: EBU
A27: Extract dry, Warm 3 | D27: °P
A28: Malts and grains
A29: Soort | D29: KG | E29: EBC | F29: TOT | G29: % | I29: Lotnummer | P29: Totaal kg:
F30: =IF(D30="-","",(D30*E30*0.08)/$C$9) | G30: =IF(D30="-","",D30/($D$40/100)) | H30: % | P30: =IF(D30="-","",D30*$G$7)
F31: =IF(D31="-","",(D31*E31*0.08)/$C$9) | G31: =IF(D31="-","",D31/($D$40/100)) | H31: % | P31: =IF(D31="-","",D31*$G$7)
F32: =IF(D32="-","",(D32*E32*0.08)/$C$9) | G32: =IF(D32="-","",D32/($D$40/100)) | H32: % | P32: =IF(D32="-","",D32*$G$7)
F33: =IF(D33="-","",(D33*E33*0.08)/$C$9) | G33: =IF(D33="-","",D33/($D$40/100)) | H33: % | P33: =IF(D33="-","",D33*$G$7)
F34: =IF(D34="-","",(D34*E34*0.08)/$C$9) | G34: =IF(D34="-","",D34/($D$40/100)) | H34: % | P34: =IF(D34="-","",D34*$G$7)
F35: =IF(D35="-","",(D35*E35*0.08)/$C$9) | G35: =IF(D35="-","",D35/($D$40/100)) | H35: % | P35: =IF(D35="-","",D35*$G$7)
F36: =IF(D36="-","",(D36*E36*0.08)/$C$9) | G36: =IF(D36="-","",D36/($D$40/100)) | H36: % | P36: =IF(D36="-","",D36*$G$7)
F37: =IF(D37="-","",(D37*E37*0.08)/$C$9) | G37: =IF(D37="-","",D37/($D$40/100)) | H37: % | P37: =IF(D37="-","",D37*$G$7)
F38: =IF(D38="-","",(D38*E38*0.08)/$C$9) | G38: =IF(D38="-","",D38/($D$40/100)) | H38: % | P38: =IF(D38="-","",D38*$G$7)
F39: =IF(D39="-","",(D39*E39*0.08)/$C$9) | G39: =IF(D39="-","",D39/($D$40/100)) | H39: % | P39: =IF(D39="-","",D39*$G$7)
A40: Totaal: | D40: =SUM(D30:D39) | F40: =SUM(F30:F39) | G40: =SUM(G30:G39) | H40: % | I40: Berekende kleur: | M40: =F40+1.75 | N40: EBC
A41: Hops and herbs
A42: Soort | D42: alpha | E42: Gram | G42: Kooktijd | I42: Rendement | K42: EBU | L42: Lotnummer | P42: Totaal gram:
K43: =IFERROR(IF(E43="-","",(E43*1000)*(D43/100)*(I43/100)/(IF(Brouwen!$F$16*100="-",$C$9*100,Brouwen!$F$16*100))),"") | P43: =IF(E43="-","",E43*$G$7)
K44: =IFERROR(IF(E44="-","",(E44*1000)*(D44/100)*(I44/100)/(IF(Brouwen!$F$16*100="-",$C$9*100,Brouwen!$F$16*100))),"") | P44: =IF(E44="-","",E44*$G$7)
...

Sheet Brouwen
A1: ='Recept-voorblad'!Q1 | C1: Brouw specificaties | P1: Bier status | S1: Invullen op de brouwdag
P2: ='Recept-voorblad'!N23
C3: Naam bier | E3: ='Recept-voorblad'!C3 | K3: Batchnummer | N3: ='Recept-voorblad'!K3 | P3: Brouwsel nr, | S3: 1 | U3: 2 | W3: 3 | Y3: 4 | AA3: 5 | AC3: 6 | AE3: 7 | AG3: 8 | AI3: 9
P4: Order nr, Software
C5: Bier stijl | E5: ='Recept-voorblad'!C7 | G5: GLT | K5: Datum 1e brouwsel | P5: Naam brouwer
P6: Start inmaischen (dd-mm uu:mm)
A7: Brouw specificaties | I7: Recept specificaties | P7: Maischen
A8: =IF(LEFT(A1,2)="WP", "Totaal volume batch","Recept nummer braukon") | H8: =IF(LEFT(A1,2)="WP", "Hl"," ") | I8: Gewenste stamwort | O8: ⁰P | P8: Maisch water | T8: hl | V8: hl | X8: hl | Z8: hl | AB8: hl | AD8: hl | AF8: hl | AH8: hl | AJ8: hl
A9: Receptnaam Software | I9: Gewenste eind plato | N9: ='Recept-voorblad'!F13 | O9: ⁰P | P9: pH na inmaischen
A10: =IF(LEFT(A1,2)="WP", "Stort special bin kg","Maischwater") | H10: =IF(LEFT(A1,2)="WP", "kg","hl") | I10: =IF(LEFT(A1,2)="WP", "Maischwater"," ") | O10: =IF(LEFT(A1,2)="WP", "hl","") | P10: Correctie zuur | T10: =IF(LEFT(A1,2)="WP","liter","ml") | V10: =IF(LEFT(A1,2)="WP","liter","ml") | X10: =IF(LEFT(A1,2)="WP","liter","ml") | Z10: =IF(LEFT(A1,2)="WP","liter","ml") | AB10: =IF(LEFT(A1,2)="WP","liter","ml") | AD10: =IF(LEFT(A1,2)="WP","liter","ml") | AF10: =IF(LEFT(A1,2)="WP","liter","ml") | AH10: =IF(LEFT(A1,2)="WP","liter","ml") | AJ10: =IF(LEFT(A1,2)="WP","liter","ml")
A11: =IF(LEFT(A1,2)="WP", "Naam special bin storting"," ") | I11: pH Maische | P11: pH na correctie
A12: Beslag dikte | F12: ="1 :"&ROUNDUP(IF(LEFT(A1,2)="WP",(N10*100)/'Recept-voorblad'!D40,(F10*100)/'Recept-voorblad'!D40),2) | I12: pH Start koken | P12: Joodnormaal test OK?
A13: =IF(LEFT(A1,2)="WP", "Cumm. Corp./sparging vol."," ") | H13: =IF(LEFT(A1,2)="WP", "hl"," ") | I13: pH Eind Koken | P13: Afwijking maische schema?
A14: Brouwsel (hl) | F14: ='Recept-voorblad'!C9 | H14: hl | I14: Beluchting | O14: =IF(LEFT(A1,2)="WP", "ppm","l/h") | P14: Spoelwater | T14: hl | V14: hl | X14: hl | Z14: hl | AB14: hl | AD14: hl | AF14: hl | AH14: hl | AJ14: hl
A15: Verwacht extract begin kook | H15: °P | I15: Wort naar gisttank Temp | N15: ='Recept-voorblad'!F21 | O15: °C | P15: Filtratie & voorloopvat
A16: Volume kook | H16: hl | I16: =IF(LEFT(A1,2)="WP", "Sparging instellingen","Filtratie volumes") | P16: Plato 1e wortvolume | T16: °P | V16: °P | X16: °P | Z16: °P | AB16: °P | AD16: °P | AF16: °P | AH16: °P | AJ16: °P
A17: Wortvoorkoeler temp | H17: °C | I17: =IF(LEFT(A1,2)="WP", "sparging 1e","1e afloop") | O17: =IF(LEFT(A1,2)="WP", "hl/h","Hl") | P17: Extract laatste afloop | T17: °P | V17: °P | X17: °P | Z17: °P | AB17: °P | AD17: °P | AF17: °P | AH17: °P | AJ17: °P
A18: =IF(LEFT(A1,2)="WP", "Volume water aditie terug koeling","Totaal volume brouwsel ") | H18: hl | I18: =IF(LEFT(A1,2)="WP", "sparging 2e","Spoelwater") | O18: =O17 | P18: Eerste afloop | T18: hl | V18: hl | X18: hl | Z18: hl | AB18: hl | AD18: hl | AF18: hl | AH18: hl | AJ18: hl
A19: =IF(LEFT(A1,2)="WP", "Eindvolume brouwsel","Eindvolume in CKT") | F19: =IF(LEFT(A1,2)="WP", 'Recept-voorblad'!C9,'Recept-voorblad'!C9*'Recept-voorblad'!G7) | H19: hl | I19: =IF(LEFT(A1,2)="WP", "sparging 3e","Spoel afloop") | O19: =O18 | P19: =IF(LEFT(A1,2)="WP", "Cumm, Sparging vol,","spoelwater") | T19: hl | V19: hl | X19: hl | Z19: hl | AB19: hl | AD19: hl | AF19: hl | AH19: hl | AJ19: hl
A20: Gewenste verdamping | H20: % | I20: =IF(LEFT(A1,2)="WP", "sparging 4e","Totaal gefiltreerd volume") | O20: =O17 | P20: =IF(LEFT(A1,2)="WP", "Last run pH","Spoelafloop")
A21: Intensiteit koken | H21: kJ/s | I21: =IF(LEFT(A1,2)="WP", "Aantal kamers Mash Filter","Lauterfactor") | P21: Filtratie tijd | T21: min | V21: min | X21: min | Z21: min | AB21: min | AD21: min | AF21: min | AH21: min | AJ21: min
A22: Whirlpool rust | H22: =IF(LEFT(A1,2)="WP", " ","min") | P22: Koken
A23: Maisch schema | I23: =IF(LEFT(A1,2)="WP", "Toevoegingen:","Extra toevoegingen") | P23: pH begin kook
A24: Inmaischen | E24: ⁰C | G24: Minuten rust | I24: Toevoegingen | L24: Hoeveelheid | N24: Moment | P24: Extract begin kook | T24: °P | V24: °P | X24: °P | Z24: °P | AB24: °P | AD24: °P | AF24: °P | AH24: °P | AJ24: °P | AK24: =AVERAGE(AI24,AG24,AE24,AC24,AA24,Y24,W24,U24,S24)
A25: Verhogen naar | E25: ⁰C | G25: Minuten rust | I25: =IF(LEFT(A1,2)="WP",IF('Recept-voorblad'!A75="","",'Recept-voorblad'!A75),IF('Recept-voorblad'!A91="-","-",IF('Recept-voorblad'!A91="Revisie nummer","",'Recept-voorblad'!A91))) | L25: =IF(LEFT($A$1,2)="WP",IF('Recept-voorblad'!E75="","",'Recept-voorblad'!E75),IF('Recept-voorblad'!E91="","",'Recept-voorblad'!E91)) | N25: =IF(LEFT($A$1,2)="WP",IF('Recept-voorblad'!I75="","",'Recept-voorblad'!I75),IF('Recept-voorblad'!I91="","",'Recept-voorblad'!I91)) | P25: V begin kook (80°C) | T25: hl | V25: hl | X25: hl | Z25: hl | AB25: hl | AD25: hl | AF25: hl | AH25: hl | AJ25: hl | AK25: =AVERAGE(AI25,AG25,AE25,AC25,AA25,Y25,W25,U25,S25)*COUNT(AI24,AG24,AE24,AC24,AA24,Y24,W24,U24,S24)
A26: Verhogen naar | E26: ⁰C | G26: Minuten rust | I26: =IF(LEFT(A1,2)="WP",IF('Recept-voorblad'!A76="","",'Recept-voorblad'!A76),IF('Recept-voorblad'!A92="-","-",IF('Recept-voorblad'!A92="Revisie nummer","",'Recept-voorblad'!A92))) | L26: =IF(LEFT($A$1,2)="WP",IF('Recept-voorblad'!E76="","",'Recept-voorblad'!E76),IF('Recept-voorblad'!E92="","",'Recept-voorblad'!E92)) | N26: =IF(LEFT($A$1,2)="WP",IF('Recept-voorblad'!I76="","",'Recept-voorblad'!I76),IF('Recept-voorblad'!I92="","",'Recept-voorblad'!I92)) | P26: Zuurcorrectie | T26: =IF(LEFT(A1,2)="WP", "liter","milliliter") | V26: =IF(LEFT(A1,2)="WP", "liter","milliliter") | X26: =IF(LEFT(A1,2)="WP", "liter","milliliter") | Z26: =IF(LEFT(A1,2)="WP", "liter","milliliter") | AB26: =IF(LEFT(A1,2)="WP", "liter","milliliter") | AD26: =IF(LEFT(A1,2)="WP", "liter","milliliter") | AF26: =IF(LEFT(A1,2)="WP", "liter","milliliter") | AH26: =IF(LEFT(A1,2)="WP", "liter","milliliter") | AJ26: =IF(LEFT(A1,2)="WP", "liter","milliliter")
A27: Verhogen naar | E27: ⁰C | G27: Minuten rust | I27: =IF(LEFT(A1,2)="WP",IF('Recept-voorblad'!A77="","",'Recept-voorblad'!A77),IF('Recept-voorblad'!A93="-","-",IF('Recept-voorblad'!A93="Revisie nummer","",'Recept-voorblad'!A93))) | L27: =IF(LEFT($A$1,2)="WP",IF('Recept-voorblad'!E77="","",'Recept-voorblad'!E77),IF('Recept-voorblad'!E93="","",'Recept-voorblad'!E93)) | N27: =IF(LEFT($A$1,2)="WP",IF('Recept-voorblad'!I77="","",'Recept-voorblad'!I77),IF('Recept-voorblad'!I93="","",'Recept-voorblad'!I93)) | P27: pH na zuurcorrectie / tijd
A28: Verhogen naar | E28: ⁰C | G28: Minuten rust | I28: =IF(LEFT(A1,2)="WP",IF('Recept-voorblad'!A78="","",'Recept-voorblad'!A78),IF('Recept-voorblad'!A94="-","-",IF('Recept-voorblad'!A94="Revisie nummer","",'Recept-voorblad'!A94))) | L28: =IF(LEFT($A$1,2)="WP",IF('Recept-voorblad'!E78="","",'Recept-voorblad'!E78),IF('Recept-voorblad'!E94="","",'Recept-voorblad'!E94)) | N28: =IF(LEFT($A$1,2)="WP",IF('Recept-voorblad'!I78="","",'Recept-voorblad'!I78),IF('Recept-voorblad'!I94="","",'Recept-voorblad'!I94)) | P28: Totale kooktijd | T28: min | V28: min | X28: min | Z28: min | AB28: min | AD28: min | AF28: min | AH28: min | AJ28: min
A29: Uitmaischen op | E29: ⁰C | G29: Minuten rust | I29: =IF(LEFT(A1,2)="WP",IF('Recept-voorblad'!A79="","",'Recept-voorblad'!A79),IF('Recept-voorblad'!A95="-","-",IF('Recept-voorblad'!A95="Revisie nummer","",'Recept-voorblad'!A95))) | L29: =IF(LEFT($A$1,2)="WP",IF('Recept-voorblad'!E79="","",'Recept-voorblad'!E79),IF('Recept-voorblad'!E95="","",'Recept-voorblad'!E95)) | N29: =IF(LEFT($A$1,2)="WP",IF('Recept-voorblad'!I79="","",'Recept-voorblad'!I79),IF('Recept-voorblad'!I95="","",'Recept-voorblad'!I95)) | P29: Verdamping | S29: =IF(S31="","",(S31-S24)/S24*100) | T29: % | U29: =IF(U31="","",(U31-U24)/U24*100) | V29: % | W29: =IF(W31="","",(W31-W24)/W24*100) | X29: % | Y29: =IF(Y31="","",(Y31-Y24)/Y24*100) | Z29: % | AA29: =IF(AA31="","",(AA31-AA24)/AA24*100) | AB29: % | AC29: =IF(AC31="","",(AC31-AC24)/AC24*100) | AD29: % | AE29: =IF(AE31="","",(AE31-AE24)/AE24*100) | AF29: % | AG29: =IF(AG31="","",(AG31-AG24)/AG24*100) | AH29: % | AI29: =IF(AI31="","",(AI31-AI24)/AI24*100) | AJ29: %
I30: =IF(LEFT(A1,2)="WP",IF('Recept-voorblad'!A80="","",'Recept-voorblad'!A80),"-") | L30: =IF(LEFT($A$1,2)="WP",IF('Recept-voorblad'!E80="","",'Recept-voorblad'!E80),"-") | N30: =IF(LEFT($A$1,2)="WP",IF('Recept-voorblad'!I80="","",'Recept-voorblad'!I80),"-") | P30: Extra toevoeging
I31: =IF(LEFT(A1,2)="WP",IF('Recept-voorblad'!A81="","",'Recept-voorblad'!A81),"-") | L31: =IF(LEFT($A$1,2)="WP",IF('Recept-voorblad'!E81="","",'Recept-voorblad'!E81),"-") | N31: =IF(LEFT($A$1,2)="WP",IF('Recept-voorblad'!I81="","",'Recept-voorblad'!I81),"-") | P31: Extract einde kook | T31: °P | V31: °P | X31: °P | Z31: °P | AB31: °P | AD31: °P | AF31: °P | AH31: °P | AJ31: °P
I32: =IF(LEFT(A1,2)="WP",IF('Recept-voorblad'!A82="","",'Recept-voorblad'!A82),"-") | L32: =IF(LEFT($A$1,2)="WP",IF('Recept-voorblad'!E82="","",'Recept-voorblad'!E82),"-") | N32: =IF(LEFT($A$1,2)="WP",IF('Recept-voorblad'!I82="","",'Recept-voorblad'!I82),"-") | P32: Whirlpool/ Einde kook
I33: =IF(LEFT(A1,2)="WP",IF('Recept-voorblad'!A83="","",'Recept-voorblad'!A83),"-") | L33: =IF(LEFT($A$1,2)="WP",IF('Recept-voorblad'!E83="","",'Recept-voorblad'!E83),"-") | N33: =IF(LEFT($A$1,2)="WP",IF('Recept-voorblad'!I83="","",'Recept-voorblad'!I83),"-") | P33: Volume whirlpool | T33: hl | V33: hl | X33: hl | Z33: hl | AB33: hl | AD33: hl | AF33: hl | AH33: hl | AJ33: hl | AK33: =AVERAGE(AI33,AG33,AE33,AC33,AA33,Y33,W33,U33,S33)*COUNT(AI33,AG33,AE33,AC33,AA33,Y33,W33,U33,S33)
I34: =IF(LEFT(A1,2)="WP",IF('Recept-voorblad'!A84="","",'Recept-voorblad'!A84),"-") | L34: =IF(LEFT($A$1,2)="WP",IF('Recept-voorblad'!E84="","",'Recept-voorblad'!E84),"-") | N34: =IF(LEFT($A$1,2)="WP",IF('Recept-voorblad'!I84="","",'Recept-voorblad'!I84),"-") | P34: Extract | T34: °P | V34: °P | X34: °P | Z34: °P | AB34: °P | AD34: °P | AF34: °P | AH34: °P | AJ34: °P | AK34: =AVERAGE(AI34,AG34,AE34,AC34,AA34,Y34,W34,U34,S34)
A35: Hop dosering | H35: HDT: | I35: =IF(LEFT(A1,2)="WP", "Automatische dosering:","receptuur additieven") | M35: =IF(LEFT(A1,2)="WP", "Zuur [L]","hoeveel&wanneer") | N35: =IF(LEFT(A1,2)="WP", "Tannines [L]","paraaf") | P35: pH
A36: Hopgift | C36: ='Recept-voorblad'!G43 | D36: min | E36: =IF(A36=" "," ", "doseerpunt") | H36: =IF(LEFT($A$1,2)="WP",IFERROR(INDEX('Recept-voorblad'!G42:Q56,MATCH(Brouwen!C36,'Recept-voorblad'!G42:G56,0),11),""),IF(IFERROR(1/INDEX('Recept-voorblad'!G42:Q56,MATCH(Brouwen!C36,'Recept-voorblad'!G42:G56,0),3),"nee")="nee",IF(Brouwen!C36="","","nee"),"ja")) | I36: =IF(LEFT(A1,2)="WP","Inmaischen",'Recept-voorblad'!A75) | L36: =IF(LEFT(A1,2)="WP", "(l/hl)"," ") | P36: Werkelijke rust tijd | T36: min | V36: min | X36: min | Z36: min | AB36: min | AD36: min | AF36: min | AH36: min | AJ36: min
A37: =IF(C37="-"," ","Hopgift") | C37: {=IFERROR(INDEX('Recept-voorblad'!G43:G57,MATCH(FALSE(),'Recept-voorblad'!G43:G57= C36,0)),"")} | D37: =IF(C37=""," ","min") | E37: =IF(A37=" "," ", "doseerpunt") | H37: =IF(LEFT($A$1,2)="WP",IFERROR(INDEX('Recept-voorblad'!G43:Q57,MATCH(Brouwen!C37,'Recept-voorblad'!G43:G57,0),11),""),IF(IFERROR(1/INDEX('Recept-voorblad'!G43:Q57,MATCH(Brouwen!C37,'Recept-voorblad'!G43:G57,0),3),"nee")="nee",IF(Brouwen!C37="","","nee"),"ja")) | I37: =IF(LEFT(A1,2)="WP", "Koken",'Recept-voorblad'!A76) | L37: =IF(LEFT(A1,2)="WP", "(L)"," ") | P37: Beluchting | T37: =O14 | V37: =T37 | X37: =T37 | Z37: =T37 | AB37: =T37 | AD37: =T37 | AF37: =T37 | AH37: =T37 | AJ37: =T37
A38: =IF(C38="-"," ","Hopgift") | C38: {=IFERROR(INDEX('Recept-voorblad'!G43:G57,MATCH(1,('Recept-voorblad'!G43:G57<C37)*('Recept-voorblad'!G43:G57<C36),0)),"")} | D38: =IF(C38=""," ","min") | E38: =IF(A38=" "," ", "doseerpunt") | H38: =IF(LEFT($A$1,2)="WP",IFERROR(INDEX('Recept-voorblad'!G44:Q58,MATCH(Brouwen!C38,'Recept-voorblad'!G44:G58,0),11),""),IF(IFERROR(1/INDEX('Recept-voorblad'!G44:Q58,MATCH(Brouwen!C38,'Recept-voorblad'!G44:G58,0),3),"nee")="nee",IF(Brouwen!C38="","","nee"),"ja")) | I38: =IF(LEFT(A1,2)="WP", "Inline sparge",'Recept-voorblad'!A77) | P38: Water additie | T38: hl | V38: hl | X38: hl | Z38: hl | AB38: hl | AD38: hl | AF38: hl | AH38: hl | AJ38: hl
A39: =IF(C39="-"," ","Hopgift") | C39: {=IFERROR(INDEX('Recept-voorblad'!G44:G58,MATCH(1,('Recept-voorblad'!G44:G58<C38)*('Recept-voorblad'!G44:G58<C37),0)),"")} | D39: =IF(C39=""," ","min") | E39: =IF(A39=" "," ", "doseerpunt") | H39: =IF(LEFT($A$1,2)="WP",IFERROR(INDEX('Recept-voorblad'!G45:Q59,MATCH(Brouwen!C39,'Recept-voorblad'!G45:G59,0),11),""),IF(IFERROR(1/INDEX('Recept-voorblad'!G45:Q59,MATCH(Brouwen!C39,'Recept-voorblad'!G45:G59,0),3),"nee")="nee",IF(Brouwen!C39="","","nee"),"ja")) | I39: =IF(LEFT(A1,2)="WP", " ",'Recept-voorblad'!A78) | M39: =IF(LEFT(A1,2)="WP"," ",'Recept-voorblad'!E78&" "&'Recept-voorblad'!I78) | P39: Volume brouwsel | S39: =IF(LEFT(A1,2)="WP","",S40) | T39: hl | U39: =IF(LEFT(A1,2)="WP","",U40-S40) | V39: hl | W39: =IF(LEFT(A1,2)="WP","",W40-U40) | X39: hl | Y39: =IF(LEFT(A1,2)="WP","",Y40-W40) | Z39: hl | AA39: =IF(LEFT(A1,2)="WP","",AA40-Y40) | AB39: hl | AC39: =IF(LEFT(A1,2)="WP","",AC40-AA40) | AD39: hl | AE39: =IF(LEFT(A1,2)="WP","",AE40-AC40) | AF39: hl | AG39: =IF(LEFT(A1,2)="WP","",AG40-AE40) | AH39: hl | AI39: =IF(LEFT(A1,2)="WP","",AI40-AG40) | AJ39: hl
A40: =IF(C40=""," ","Hopgift") | C40: {=IFERROR(INDEX('Recept-voorblad'!G45:G59,MATCH(1,('Recept-voorblad'!G45:G59<C39)*('Recept-voorblad'!G45:G59<C38),0)),"")} | D40: =IF(C40=""," ","min") | E40: =IF(A40=" "," ", "doseerpunt") | H40: =IFERROR(INDEX('Recept-voorblad'!G46:Q60,MATCH(Brouwen!C40,'Recept-voorblad'!G46:G60,0),11),"") | I40: =IF(LEFT(A1,2)="WP", " ",'Recept-voorblad'!A79) | M40: =IF(LEFT(A1,2)="WP"," ",'Recept-voorblad'!E79&" "&'Recept-voorblad'!I79) | P40: Volume GLT | S40: =IFERROR(IF(LEFT(A1,2)="WP",S39+S38," "),"") | T40: hl | U40: =IFERROR(IF(LEFT(A1,2)="WP",U39+U38+S40," "),"") | V40: hl | W40: =IFERROR(IF(LEFT(A1,2)="WP",W39+W38+U40," "),"") | X40: hl | Y40: =IFERROR(IF(LEFT(A1,2)="WP",Y39+Y38+W40," "),"") | Z40: hl | AA40: =IFERROR(IF(LEFT(A1,2)="WP",AA39+AA38+Y40," "),"") | AB40: hl | AC40: =IFERROR(IF(LEFT(A1,2)="WP",AC39+AC38+AA40," "),"") | AD40: hl | AE40: =IFERROR(IF(LEFT(A1,2)="WP",AE39+AE38+AC40," "),"") | AF40: hl | AG40: =IFERROR(IF(LEFT(A1,2)="WP",AG39+AG38+AE40," "),"") | AH40: hl | AI40: =IFERROR(IF(LEFT(A1,2)="WP",AI39+AI38+AG40," "),"") | AJ40: hl | AK40: =MAX(S40,U40,W40,Y40,AA40,AC40,AE40,AG40,AI40)
...

Sheet Gistkaart Invoer
K1: Specificaties
A2: Batch | D2: GLT | E2: LT | H2: =CHOOSE(WEEKDAY(H4),"Zondag","Maandag","Dinsdag","Woensdag","Donderdag","Vrijdag","Zaterdag") | K2: Parameter | N2: Unit | O2: Spec | P2: +/- | Q2: Parameter | S2: Unit | T2: Spec | U2: +/-
K3: Original extract | N3: °P | O3: ='Recept-voorblad'!F12 | P3: ='Recept-voorblad'!E12 | Q3: Lager temp, | S3: °C | T3: ='Recept-voorblad'!M23 | X3: =IF(COUNTIF('Recept-voorblad'!G58:I63,"warm")>0,IF(SUMIF('Recept-voorblad'!G58:P63,"warm",'Recept-voorblad'!P58:P63)= ">65000","Dry hop methode= "&"warm hopsteiner","Dry hop methode= "&"warm hopgun"),"")
A4: ='Recept-voorblad'!C3 | D4: =Brouwen!I5 | H4: =TODAY() | K4: ='Recept-voorblad'!A23 | N4: °C | O4: ='Recept-voorblad'!F23 | P4: ='Recept-voorblad'!E23 | Q4: Lagering time | S4: days | T4: ='Recept-voorblad'!M22 | X4: =ROUND(SUMIF('Recept-voorblad'!G55:P60,"warm",'Recept-voorblad'!P55:P60)/1000,1)&" kilogram dry hop"
K5: Temp, Warm dryhop 1 | N5: °C | O5: ='Recept-voorblad'!F24 | P5: ='Recept-voorblad'!E24 | Q5: Rest extract | S5: °P | T5: ='Recept-voorblad'!F13 | U5: ='Recept-voorblad'!E13
K6: Extract warm dryhop 1 | N6: °P | O6: ='Recept-voorblad'!F25 | P6: ='Recept-voorblad'!E25 | Q6: pH end product | T6: ='Recept-voorblad'!F17 | U6: ='Recept-voorblad'!E17 | X6: =IF(COUNTIF('Recept-voorblad'!G58:I63," @16C")>0,IF(SUMIF('Recept-voorblad'!G58:P63," @16C",'Recept-voorblad'!P58:P63)= ">65000","Dry hop methode= "&"@16C hopsteiner","Dry hop methode= "&" @16C hopgun"),"")
K7: Extract warm dryhop 2 | N7: °P | O7: ='Recept-voorblad'!F26 | P7: ='Recept-voorblad'!E26 | Q7: Alcohol | S7: %v/v | T7: ='Recept-voorblad'!F14 | U7: ='Recept-voorblad'!E14 | X7: =ROUND(SUMIF('Recept-voorblad'!G58:P63," @16C",'Recept-voorblad'!P58:P63)/1000,1)&" kilogram dry hop"
B8: Bier risico | D8: Bier status | K8: Extract warm dryhop 3 | N8: °P | O8: ='Recept-voorblad'!F27 | P8: ='Recept-voorblad'!E27 | Q8: Berekeningen
B9: ='Recept-voorblad'!N17 | D9: ='Recept-voorblad'!N23 | K9: Fermentation time | N9: days | O9: ='Recept-voorblad'!M21 | Q9: ADF | S9: %w/w | T9: {=IF(B13="","",(($B$13-(INDEX($B$13:$B$31,COUNTA($B$13:$B$31))))/$B$13)*100)} | X9: Cellar addition
Q10: Theoretical ABV | S10: %v/v | T10: {=IF(B13="","",($B$13-(INDEX($B$13:$B$31,COUNTA($B$13:$B$31))))*0.533)}
A12: Dagen | B12: Plato | C12: Temp Hoog | D12: Temp Laag | E12: pH | F12: div, | G12: Timer | H12: Plato afname | I12: Tijd tussen meting | J12: Datum | K12: Tijd | L12: Actie | O12: Opmerkingen | U12: Operator
A13: =+J13-$J$13+K13/24-$K$13/24 | B13: =IF(Brouwen!AG41="",IF(Brouwen!AE41="",IF(Brouwen!AC41="",IF(Brouwen!AA41="",IF(Brouwen!Y41="",IF(Brouwen!W41="",IF(Brouwen!U41="",Brouwen!S41,Brouwen!U41),Brouwen!W41),Brouwen!Y41),Brouwen!AA41),Brouwen!AC41),Brouwen!AE41),Brouwen!AG41) | E13: =IF(Brouwen!S35="","",AVERAGE(Brouwen!S35,Brouwen!U35,Brouwen!W35,Brouwen!Y35,Brouwen!AA35,Brouwen!AC35,Brouwen!AE35,Brouwen!AG35,Brouwen!AI35)) | J13: =TRUNC(IF(Brouwen!AG6="",IF(Brouwen!AE6="",IF(Brouwen!AC6="",IF(Brouwen!AA6="",IF(Brouwen!Y6="",IF(Brouwen!W6="",IF(Brouwen!U6="",Brouwen!S6,Brouwen!U6),Brouwen!W6),Brouwen!Y6),Brouwen!AA6),Brouwen!AC6),Brouwen!AE6),Brouwen!AG6)) | O13: laatste brouwsel
A14: =+J14-$J$13+K14/24-$K$13/24 | G14: =IF(K14="","",(B14-F14)/(H14+0.000001)*I14) | H14: =IF(B14="","",(B13-B14)) | I14: =IF(K14="","",24*(A14-A13))
A15: =+J15-$J$13+K15/24-$K$13/24 | G15: =IF(K15="","",(B15-F15)/(H15+0.000001)*I15) | H15: =IF(B15="","",(B14-B15)) | I15: =IF(K15="","",24*(A15-A14))
A16: =+J16-$J$13+K16/24-$K$13/24 | G16: =IF(K16="","",(B16-F16)/(H16+0.000001)*I16) | H16: =IF(B16="","",(B15-B16)) | I16: =IF(K16="","",24*(A16-A15))
A17: =+J17-$J$13+K17/24-$K$13/24 | G17: =IF(K17="","",(B17-F17)/(H17+0.000001)*I17) | H17: =IF(B17="","",(B16-B17)) | I17: =IF(K17="","",24*(A17-A16))
A18: =+J18-$J$13+K18/24-$K$13/24 | G18: =IF(K18="","",(B18-F18)/(H18+0.000001)*I18) | H18: =IF(B18="","",(B17-B18)) | I18: =IF(K18="","",24*(A18-A17))
A19: =+J19-$J$13+K19/24-$K$13/24 | G19: =IF(K19="","",(B19-F19)/(H19+0.000001)*I19) | H19: =IF(B19="","",(B18-B19)) | I19: =IF(K19="","",24*(A19-A18))
A20: =+J20-$J$13+K20/24-$K$13/24 | G20: =IF(K20="","",(B20-F20)/(H20+0.000001)*I20) | H20: =IF(B20="","",(B19-B20)) | I20: =IF(K20="","",24*(A20-A19))
A21: =+J21-$J$13+K21/24-$K$13/24 | G21: =IF(K21="","",(B21-F21)/(H21+0.000001)*I21) | H21: =IF(B21="","",(B20-B21)) | I21: =IF(K21="","",24*(A21-A20))
A22: =+J22-$J$13+K22/24-$K$13/24 | G22: =IF(K22="","",(B22-F22)/(H22+0.000001)*I22) | H22: =IF(B22="","",(B21-B22)) | I22: =IF(K22="","",24*(A22-A21))
A23: =+J23-$J$13+K23/24-$K$13/24 | G23: =IF(K23="","",(B23-F23)/(H23+0.000001)*I23) | H23: =IF(B23="","",(B22-B23)) | I23: =IF(K23="","",24*(A23-A22)) | O23: =IF('Recept-voorblad'!I91="-","-",'Recept-voorblad'!E91&" "&'Recept-voorblad'!A91&" @"&'Recept-voorblad'!I91)
A24: =+J24-$J$13+K24/24-$K$13/24 | G24: =IF(K24="","",(B24-F24)/(H24+0.000001)*I24) | H24: =IF(B24="","",(B23-B24)) | I24: =IF(K24="","",24*(A24-A23)) | O24: =IF('Recept-voorblad'!I92="-","-",'Recept-voorblad'!E92&" "&'Recept-voorblad'!A92&" @"&'Recept-voorblad'!I92)
A25: =+J25-$J$13+K25/24-$K$13/24 | G25: =IF(K25="","",(B25-F25)/(H25+0.000001)*I25) | H25: =IF(B25="","",(B24-B25)) | I25: =IF(K25="","",24*(A25-A24)) | O25: =IF('Recept-voorblad'!I93="-","-",'Recept-voorblad'!E93&" "&'Recept-voorblad'!A93&" @"&'Recept-voorblad'!I93)
A26: =+J26-$J$13+K26/24-$K$13/24 | G26: =IF(K26="","",(B26-F26)/(H26+0.000001)*I26) | H26: =IF(B26="","",(B25-B26)) | I26: =IF(K26="","",24*(A26-A25)) | O26: =IF('Recept-voorblad'!I94="-","-",'Recept-voorblad'!E94&" "&'Recept-voorblad'!A94&" @"&'Recept-voorblad'!I94)
A27: =+J27-$J$13+K27/24-$K$13/24 | G27: =IF(K27="","",(B27-F27)/(H27+0.000001)*I27) | H27: =IF(B27="","",(B26-B27)) | I27: =IF(K27="","",24*(A27-A26)) | O27: =IF('Recept-voorblad'!I95="-","-",'Recept-voorblad'!E95&" "&'Recept-voorblad'!A95&" @"&'Recept-voorblad'!I95)
A28: =+J28-$J$13+K28/24-$K$13/24 | G28: =IF(K28="","",(B28-F28)/(H28+0.000001)*I28) | H28: =IF(B28="","",(B27-B28)) | I28: =IF(K28="","",24*(A28-A27))
A29: =+J29-$J$13+K29/24-$K$13/24 | G29: =IF(K29="","",(B29-F29)/(H29+0.000001)*I29) | H29: =IF(B29="","",(B28-B29)) | I29: =IF(K29="","",24*(A29-A28))
A30: =+J30-$J$13+K30/24-$K$13/24 | G30: =IF(K30="","",(B30-F30)/(H30+0.000001)*I30) | H30: =IF(B30="","",(B29-B30)) | I30: =IF(K30="","",24*(A30-A29))
A31: =+J31-$J$13+K31/24-$K$13/24 | G31: =IF(K31="","",(B31-F31)/(H31+0.000001)*I31) | H31: =IF(B31="","",(B30-B31)) | I31: =IF(K31="","",24*(A31-A30))
A32: =+J32-$J$13+K32/24-$K$13/24 | G32: =IF(K32="","",(B32-F32)/(H32+0.000001)*I32) | H32: =IF(B32="","",(B31-B32)) | I32: =IF(K32="","",24*(A32-A31))
A33: =+J33-$J$13+K33/24-$K$13/24 | G33: =IF(K33="","",(B33-F33)/(H33+0.000001)*I33) | H33: =IF(B33="","",(B32-B33)) | I33: =IF(K33="","",24*(A33-A32))
A34: =+J34-$J$13+K34/24-$K$13/24 | G34: =IF(K34="","",(B34-F34)/(H34+0.000001)*I34) | H34: =IF(B34="","",(B33-B34)) | I34: =IF(K34="","",24*(A34-A33))
A35: =+J35-$J$13+K35/24-$K$13/24 | G35: =IF(K35="","",(B35-F35)/(H35+0.000001)*I35) | H35: =IF(B35="","",(B34-B35)) | I35: =IF(K35="","",24*(A35-A34))
A36: =+J36-$J$13+K36/24-$K$13/24 | G36: =IF(K36="","",(B36-F36)/(H36+0.000001)*I36) | H36: =IF(B36="","",(B35-B36)) | I36: =IF(K36="","",24*(A36-A35))
A37: =+J37-$J$13+K37/24-$K$13/24 | G37: =IF(K37="","",(B37-F37)/(H37+0.000001)*I37) | H37: =IF(B37="","",(B36-B37)) | I37: =IF(K37="","",24*(A37-A36))
A38: =+J38-$J$13+K38/24-$K$13/24 | G38: =IF(K38="","",(B38-F38)/(H38+0.000001)*I38) | H38: =IF(B38="","",(B37-B38)) | I38: =IF(K38="","",24*(A38-A37)) | AB38: datum
A39: =+J39-$J$13+K39/24-$K$13/24 | G39: =IF(K39="","",(B39-F39)/(H39+0.000001)*I39) | H39: =IF(B39="","",(B38-B39)) | I39: =IF(K39="","",24*(A39-A38)) | X39: =_xlfn.IFNA(IF(AB39>0,"x","-"),"-") | Z39: dry warm | AB39: {=INDEX(J11:L42,MATCH("*"&Z39&"*",TEXT(L11:L42,0),0),1)}
A40: =+J40-$J$13+K40/24-$K$13/24 | G40: =IF(K40="","",(B40-F40)/(H40+0.000001)*I40) | H40: =IF(B40="","",(B39-B40)) | I40: =IF(K40="","",24*(A40-A39))
A41: =+J41-$J$13+K41/24-$K$13/24 | G41: =IF(K41="","",(B41-F41)/(H41+0.000001)*I41) | H41: =IF(B41="","",(B40-B41)) | I41: =IF(K41="","",24*(A41-A40)) | X41: =_xlfn.IFNA(IF(AB41>0,"x","-"),"-") | Z41: dryhopping | AB41: {=INDEX(J11:L42,MATCH("*"&Z41&"*",TEXT(L11:L42,0),0),1)}
...

Sheet Verwerking
A1: Verwerking | S1: =D63
S2: =R62
A3: Beer name | C3: ='Gistkaart Invoer'!A4 | I3: Batchnummer: | L3: ='Recept-voorblad'!K3
S4: Check before processing:
A5: Specificaties | P5: Beer risk category | T5: - Minimum maturation = 5 days.
A6: Parameter | D6: unit | E6: spec, | G6: +/- | H6: Parameter | M6: unit | N6: spec, | O6: +/- | P6: ='Recept-voorblad'!N17 | T6: - Cellar adds completed
A7: Turbidity after centrifuge | D7: EBC | E7: ='Recept-voorblad'!M25 | G7: ='Recept-voorblad'!L25 | H7: CO2 spec HBT bottle | M7: g/l | N7: ='Recept-voorblad'!M13 | O7: ='Recept-voorblad'!L13-0.1 | T7: - CO2 spec bottle & can both in SAME HBT =
A8: Pasteurisation | D8: PU | E8: ='Recept-voorblad'!M24 | G8: 2 | H8: CO2 spec HBT KEG | M8: g/l | N8: ='Recept-voorblad'!M15 | O8: ='Recept-voorblad'!L15+0.2 | T8: middle between both specs
A9: O2 in HBT | D9: ppb | E9: 50 | G9: < | H9: CO2 spec HBT Can | N9: ='Recept-voorblad'!M14 | O9: ='Recept-voorblad'!L14-0.1
A10: Lagering
A11: O.G. GLT | D11: O2 | F11: CO2 | H11: Start date lagering
A12: Measurement after pushing over: | E12: ppb | G12: g/l | H12: Days on lagering | N12: =IF(D16="","",(D16-N11)) | P12: days
A13: Verwerking
A14: Name operator start | I14: Start of processing:
A15: Name operator end | I15: End of processing: | S15: Attention: put Alcohol as vol% (=ABV%)
A16: Date of processing | I16: Duration of processing: | P16: =IF(P15="","",(P15-P14)) | S16: Volume Mooie Nel | U16: --> | V16: 950 | W16: liter
S17: Alcohol Mooie Nel - batch | U17: =V22 | V17: 6.95 | W17: %ABV
A18: Processed from (G)LT: | G18: Standpijp | J18: General info | S18: Gewenste alcohol Super Dupa --> | V18: 5.5 | W18: %ABV
D19: O2 | G19: CO2 | S19: Volume after dilution | V19: =(V16+V20) | W19: liter
A20: Values in (G)LT before start | F20: ppb | I20: g/l | J20: Losses | L20: 1 | M20: frequency | O20: 10 | Q20: Minutes | S20: to be added amount of water | V20: =(V17-V18)*V16/V18 | W20: liter
A21: Centrifuge start out | F21: ppb | I21: g/l | J21: Flow [hl/u] | M21: HL processed [hl] | P21: Turbidity [EBC] | R21: Bypass [%]
F22: ppb | I22: g/l | S22: Made from batch Mooie Nel
F23: ppb | I23: g/l | S23: Effective pushed-over volume | W23: liter
F24: ppb | I24: g/l | S24: Effective water added | W24: liter
A25: Pasteurised with | F25: PU | G25: Avg. Temp out | L25: °C | M25: Avg. Turbidity | R25: EBC | T25: fill in all yellow cells
A26: Time [hh:mm] | C26: Comments processing
A31: Comments tasting | Q31: Go or Not Go? | R31: -
A32: Bright beer tanks (HBT):
M33: Comments | T33: fill in yellow cells only
A34: HBT | D34: HL | F34: ppb | I34: g/l | J34: Can | T34: NAGARDO ADD calculator #1
A35: HBT | D35: HL | F35: ppb | I35: g/l | J35: Bottle | S35: Volume to process in HBT | U35: 11 | V35: 60 | W35: HL
A36: HBT | D36: HL | F36: ppb | I36: g/l | J36: KEG | S36: Dosing (from recept-voorblad) | V36: =VLOOKUP("*Nagardo*",'Recept-voorblad'!$A$91:$H$93,5,FALSE()) | W36: ppm
A37: HBT | D37: HL | F37: ppb | I37: g/l | J37: Fill in | S37: Nagardo weight (calc-ed) | V37: =V35*V36/1000*100 | W37: gram
A38: HBT | D38: HL | F38: ppb | I38: g/l | J38: Can | S38: Volume water (calc-ed) | V38: =V37/(1000*0.01) | W38: liter
A39: HBT | D39: HL | F39: ppb | I39: g/l | J39: Fill in | S39: Calculation correct? | U39: initials | V39: Yes/No
A40: HBT | D40: HL | F40: ppb | I40: g/l | J40: Fill in | S40: Operator #1 | V40: No
A41: HBT | D41: HL | F41: ppb | I41: g/l | J41: Fill in | S41: Operator #2 | V41: No
A42: HBT | D42: HL | F42: ppb | I42: g/l | J42: Fill in | S42: Laboratory | V42: No
A43: HBT | D43: HL | F43: ppb | I43: g/l | J43: Fill in | T43: PGA - Alginate add calculator
A44: HBT | D44: HL | F44: ppb | I44: g/l | J44: Fill in | S44: Alginate | V44: =V46*0.02*1000 | W44: gram
...

Sheet Afvullen
A1: Afvullen
A3: Naam bier | C3: =Verwerking!C3 | D3: Batchnummer: | E3: ='Recept-voorblad'!K3 | I3: Afvullingen
A5: Productie opdracht specificaties | D5: controleur | E5: Bier risico | M5: Datum | N5: Datum | O5: Datum | P5: Datum | Q5: Datum | R5: Datum
A6: EAN doos fles 24x33cl: | E6: ='Recept-voorblad'!N17
A7: EAN doos fles 12x33cl: | M7: HBT nr | N7: HBT nr | O7: HBT nr | P7: HBT nr | Q7: HBT nr | R7: HBT nr
A8: EAN doos blik 24x33cl:
A9: EAN doos blik 12x33cl: | M9: Start Afvul | N9: Start Afvul | O9: Start Afvul | P9: Start Afvul | Q9: Start Afvul | R9: Start Afvul
A10: Codering fles: | M10: 0 | N10: 0 | O10: 0 | P10: 0 | Q10: 0 | R10: 0
A11: Codering blik: | M11: Einde Afvul | N11: Einde Afvul | O11: Einde Afvul | P11: Einde Afvul | Q11: Einde Afvul | R11: Einde Afvul
A12: Codering vat: | M12: 0 | N12: 0 | O12: 0 | P12: 0 | Q12: 0 | R12: 0
A13: Dag nummer | C13: =TODAY()-DATE(2023,12,31) | I13: Afgevuld door:
A14: Productie opdracht
A15: Fles Afvul 1,
A16: Flessoort: | D16: Doossoort: | I16: Monstername door:
A17: Etiketten: | D17: Codering doos: | I17: Controle 1e verpakking (twee operators):
A18: Codering fles: | D18: Ean code doos: | I18: Vulpijp-detectiecontrole 1e verpakking:
A19: Kroonkurk: | D19: Logo doos: | I19: Vulpijp-detectiecontrole einde batch:
A20: Fles Afvul 2, | I20: Klapflessen
A21: Flessoort: | D21: Doossoort: | I21: Klapfles beheerst? | M21: Y/N | N21: Y/N | O21: Y/N | P21: Y/N | Q21: Y/N | R21: Y/N
A22: Etiketten: | D22: Codering doos:
A23: Codering fles: | D23: Ean code doos: | I23: Parameter | J23: [unit] | K23: spec, | L23: +/- | M23: waarde | N23: waarde | O23: waarde | P23: waarde | Q23: waarde | R23: waarde | T23: pack type | U23: can 330ml
A24: Kroonkurk: | D24: Logo doos: | I24: time | T24: weigh MT | V24: g
A25: Fles Afvul 3, | I25: TPO Fles / Can 1 | J25: [ppb] | K25: ='Recept-voorblad'!$M$16+'Recept-voorblad'!$M$17 | L25: < | T25: contents 1 | V25: g
A26: Flessoort: | D26: Doossoort: | I26: HSO Fles / Can 1 | J26: [ppb] | K26: ='Recept-voorblad'!$M$16 | L26: ='Recept-voorblad'!$L$16 | T26: contents 2 | V26: g
A27: Etiketten: | D27: Codering doos: | I27: DO Fles / Can 1 | J27: [ppb] | K27: ='Recept-voorblad'!$M$17 | T27: contents 3 | V27: g
A28: Codering fles: | D28: Ean code doos: | I28: HS vol. | T28: contents 4 | V28: g
A29: Kroonkurk: | D29: Logo doos: | I29: Druk | T29: contents 5 | V29: g
A30: Blik Afvul 1, | I30: Temp(00C) | T30: contents 6 | V30: g
A31: bliksoort: | D31: Doossoort: | I31: CO2 Fles / Can 1 (200C) | J31: [g/l] | K31: ='Recept-voorblad'!$M$13 | L31: ='Recept-voorblad'!$L$13 | T31: contents 7 | V31: g
A32: Etiketten: | D32: Codering doos: | I32: CO2 Fust 1 | J32: [g/l] | K32: ='Recept-voorblad'!$M$15 | L32: ='Recept-voorblad'!$L$15 | T32: contents 8 | V32: g
A33: Codering blik: | D33: Ean code doos: | I33: Zuurstof Fust 1 | J33: [ppb] | K33: ='Recept-voorblad'!$M$17 | L33: ='Recept-voorblad'!$L$17 | T33: contents 9 | V33: g
A34: deksel: | D34: Logo doos: | I34: time | T34: contents 10 | V34: g
A35: Blik Afvul 2, | I35: TPO Fles / Can 2 | J35: [ppb] | K35: ='Recept-voorblad'!$M$16+'Recept-voorblad'!$M$17 | L35: < | T35: contents 11 | V35: g
A36: bliksoort: | D36: Doossoort: | I36: HSO Fles / Can 2 | J36: [ppb] | K36: ='Recept-voorblad'!$M$16 | L36: ='Recept-voorblad'!$L$16 | T36: contents 12 | V36: g
A37: Etiketten: | D37: Codering doos: | I37: DO Fles / Can 2 | J37: [ppb] | K37: ='Recept-voorblad'!$M$17 | T37: contents 13 | V37: g
A38: Codering blik: | D38: Ean code doos: | I38: HS vol. | T38: contents 14 | V38: g
A39: deksel: | D39: Logo doos: | I39: Druk | T39: contents 15 | V39: g
A40: Fust Afvul 1, | I40: Temp(00C) | T40: contents 16 | V40: g
A41: Fustmaat: | D41: Logo: | I41: CO2 Fles / Can 2 (200C) | J41: [g/l] | K41: ='Recept-voorblad'!$M$13 | L41: ='Recept-voorblad'!$L$13 | T41: contents 17 | V41: g
A42: Ean code: | I42: CO2 Fust 2 | J42: [g/l] | K42: ='Recept-voorblad'!$M$15 | L42: ='Recept-voorblad'!$L$15 | T42: contents 18 | V42: g
...

Sheet Afvulverslag
B1: Afvulverslag | M1: TOTALEN
B3: Naam Bier | C3: =Afvullen!C3 | F3: Batch | H3: ='Recept-voorblad'!K3 | M3: Totaal HL's van Verwer- king (Liters) | O3: Totaal Afgevuld | Q3: Nog te doen / restant / verlies
B5: Opmerkingen bij afvullen | O5: (liters) | Q5: (liters) | R5: %
D6: Datum | E6: Datum | F6: Datum | G6: Datum | H6: Datum | I6: Datum | M6: =Verwerking!D63*100 | O6: =(M9+M11+M13+Q9) | Q6: =M6-O6 | R6: =1-O6/M6
D8: HBT nr | E8: HBT nr | F8: HBT nr | G8: HBT nr | H8: HBT nr | I8: HBT nr | M8: Totaal Liters Fles | Q8: Totaal Liters Blik
M9: =SUM(M17:M26) | Q9: =SUM(M28:M31)
D10: Volume (HL) | E10: Volume (HL) | F10: Volume (HL) | G10: Volume (HL) | H10: Volume (HL) | I10: Volume (HL) | M10: Totaal Liters Fust
M11: =SUM(M34:M41)
M12: Totaal samengevoegd
A13: =+J13-$J$13+K13/24-$K$13/24 | B13: Ingevuld door | C13: Naam | M13: =SUM(K44:K46)
K15: OPBOEKEN (+)
B16: AFVUL FLESSEN | C16: EAN | D16: Aantallen | E16: Aantallen | F16: Aantallen | G16: Aantallen | H16: Aantallen | I16: Aantallen | K16: TOTALEN | M16: LITERS
B17: Doos 24x33cl | C17: =Afvullen!C6 | K17: =SUM(D17:I17) | M17: =K17*0.33*24
B18: Doos 24x33cl - BLANCO | C18: =C17 | K18: =SUM(D18:I18) | M18: =K18*0.33*24
B20: Doos 12x33cl | C20: =Afvullen!C7 | K20: =SUM(D20:I20) | M20: =K20*0.33*12
B21: Doos 12x33cl - BLANCO | C21: =C20 | K21: =SUM(D21:I21) | M21: =K21*0.33*12
B23: Doos 6x75cl | K23: =SUM(D23:I23) | M23: =K23*6*0.75
B24: Doos 6x75cl - BLANCO | C24: =C23 | K24: =SUM(D24:I24) | M24: =K24*6*0.75
B25: Krat 12x75cl - BLANCO | K25: =SUM(D25:I25) | M25: =K25*12*0.75
K26: ='Recept-voorblad'!$M$13
B27: AFVUL BLIKKEN | C27: Opmerkingen | D27: Aantallen | E27: Aantallen | F27: Aantallen | G27: Aantallen | H27: Aantallen | I27: Aantallen | K27: TOTALEN | M27: LITERS
B28: Doos 12x33cl Blik | C28: =Afvullen!C9 | K28: =SUM(D28:I28) | M28: =K28*0.33*12
B29: Doos 24x33cl Blik | C29: =Afvullen!C8 | K29: =SUM(D29:I29) | M29: =K29*0.33*24
B30: Doos 12x44cl Blik | C30: =Afvullen!C9 | K30: =SUM(D30:I30) | M30: =K30*0.44*12
B31: Doos 24x44cl Blik | C31: =Afvullen!C10 | K31: =SUM(D31:I31) | M31: =K31*0.44*24
B33: AFVUL FUSTEN & KEYKEGS | C33: Opmerkingen | D33: Aantallen | E33: Aantallen | F33: Aantallen | G33: Aantallen | H33: Aantallen | I33: Aantallen | K33: TOTALEN | M33: LITERS
B34: 20L KeyKeg | K34: =SUM(D34:I34) | M34: =K34*20
B35: 20L KU Fust | K35: =SUM(D35:I35) | M35: =K35*20
B36: 30L Jopen Fust | K36: =SUM(D36:I36) | M36: =K36*30
B37: 50L Jopen Fust | K37: =SUM(D37:I37) | M37: =K37*50
B39: 20L Gbr. Door Vrouwen fust | K39: =SUM(D39:I39) | M39: =K39*20
B40: 20L Other kegs | K40: =SUM(D40:I40) | M40: =K40*20
B41: 30L KeyKeg | K41: =SUM(D41:I41) | M41: =K41*30
B43: GEBRUIKT TBV SAMENVOEGEN / BARREL AGING | C43: Opmerkingen | D43: Liters | E43: Liters | F43: Liters | G43: Liters | H43: Liters | I43: Liters | K43: TOTALEN Liters
B44: TBV BATCH …, | K44: =SUM(D44:I44) | M44: =K44
B45: TBV BARREL AGING BATCH… | K45: =SUM(D45:I45) | M45: =K45
K46: =SUM(D46:I46)
B48: VERBRUIKEN : | K48: UITSCHRIJVEN (-)
B49: VERBRUIKEN FLES | C49: Opmerkingen | D49: Aantal | E49: Aantal | F49: Aantal | G49: Aantal | H49: Aantal | I49: Aantal | K49: TOTALEN | M49: VERLIES
B50: Fles 33cl | K50: =SUM(D50:I50) | M50: =K50-SUM(K17:K18)*24-SUM(K20:K21)*12
...
